Workbook
Name Current_Year_Plans: '[1]Master '!$C$71:$C$138
Name Gold19: Data!$B$2
Name Previous_Year_Plans: '[1]Master '!$C$2:$C$69

Sheet Gold 1
B1: SimplyBlue Plus Gold 1 | D1: SimplyBlue Plus Gold 5 | F1: SimplyBlue Plus Gold 6
A2: Single | B2: 681.83 | D2: 695.29 | F2: 652.67
A3: Subscriber & Spouse | B3: 1363.65 | D3: 1390.57 | F3: 1305.33
A4: Subscriber & Child(ren) | B4: 1159.11 | D4: 1181.99 | F4: 1109.53
A5: Family | B5: 1943.21 | D5: 1981.57 | F5: 1860.1
A6: Primary Care Office Visit | B6: $25 copay per visit | C6: Covered at 80%, subject to the deductible | D6: $40 copay per visit | E6: Covered at 80%, subject to the deductible | F6: Covered at 80%, subject to the deductible | G6: Covered at 60%, subject to the deductible
A7: Specialist Office Visit | B7: $50 copay per visit | C7: Covered at 80%, subject to the deductible | D7: $70 copay per visit | E7: Covered at 80%, subject to the deductible | F7: Covered at 80%, subject to the deductible | G7: Covered at 60%, subject to the deductible
A8: Coinsurance | B8: None | C8: Covered at 80% | D8: None | E8: Covered at 80% | F8: Covered at 80% | G8: Covered at 60%
A9: Deductible | B9: None | C9: Out-of-Network: $5,000 Individual / $10,000 Family | D9: None | E9: Out-of-Network: $5,000 Individual / $10,000 Family | F9: In-Network: $1,600 Individual / | G9: Out-of-Network: $5,000 Individual / $10,000 Family
F10: $3,200 Family
A11: Out of pocket maximum | B11: $7,900 Individual / $15,800 Family | C11: $10,000 Individual / $20,000 Family | D11: $8,000 Individual / $16,000 Family | E11: $10,000 Individual / $20,000 Family | F11: $3,200 Individual / $6,400 Family | G11: $10,000 Individual / $20,000 Family
A12: Well child visits | B12: Covered In Full | C12: Covered at 80%, subject to the deductible | D12: Covered In Full | E12: Covered at 80%, subject to the deductible | F12: Covered In Full | G12: Covered at 60%, subject to the deductible
A13: +Adult immunizations | B13: Covered In Full | C13: Covered at 80%, subject to the deductible | D13: Covered In Full | E13: Covered at 80%, subject to the deductible | F13: Covered In Full | G13: Covered at 60%, subject to the deductible
A14: Routine GYN Exam | B14: Covered In Full | C14: Covered at 80%, subject to the deductible | D14: Covered In Full | E14: Covered at 80%, subject to the deductible | F14: Covered In Full | G14: Covered at 60%, subject to the deductible
A15: +Prostate cancer screening | B15: Covered In Full | C15: Covered at 80%, subject to the deductible | D15: Covered In Full | E15: Covered at 80%, subject to the deductible | F15: Covered In Full | G15: Covered at 60%, subject to the deductible
A16: Telemedicine and Telehealth Services | B16: Covered In Full | C16: Covered at 80%, subject to the deductible | D16: Covered In Full | E16: Covered at 80%, subject to the deductible | F16: Covered In Full, subject to deductible | G16: Covered at 60%, subject to the deductible
A17: Diagnostic x-rays | B17: $50 copay per visit | C17: Covered at 80%, subject to the deductible | D17: $70 copay per visit | E17: Covered at 80%, subject to the deductible | F17: Covered at 80%, subject to the deductible | G17: Covered at 60%, subject to the deductible
A18: Diagnostic laboratory and | B18: $50 copay per visit | C18: Covered at 80%, subject to | D18: $40 copay per visit | E18: Covered at 80%, subject to | F18: Covered at 80%, subject to | G18: Covered at 60%, subject to
A19: Chemotherapy | B19: $25 copay per visit | C19: Covered at 80%, subject to the deductible | D19: $40 copay per visit | E19: Covered at 80%, subject to the deductible | F19: Covered at 80%, subject to the deductible | G19: Covered at 60%, subject to the deductible
A20: Radiation therapy | B20: $50 copay per visit | C20: Covered at 80%, subject to the deductible | D20: $70 copay per visit | E20: Covered at 80%, subject to the deductible | F20: Covered at 80%, subject to the deductible | G20: Covered at 60%, subject to the deductible
A21: Prenatal care | B21: Covered in full (Cost share may apply to ultrasounds, lab work and sick visits) | C21: Covered at 80%, subject to the deductible per admission | D21: Covered in full (Cost share may apply to ultrasounds, lab work and sick visits) | E21: Covered at 80%, subject to the deductible per admission | F21: Covered in full (Cost share may apply to ultrasounds, lab work and sick visits) | G21: Covered at 60%, subject to the deductible
A22: Prescription Drug Coverage | B22: $15/40%/50% | C22: Not Covered | D22: $15/$75/50% | E22: Not Covered | F22: $5/$35/$70, subject to the plan deductible. Preventive drugs are not subject to the deductible; they are subject to the applicable copay or coinsurance. | G22: Not Covered
... A35: Adult Eyewear | B35: Eyewear Reimbursement of | C35: Eyewear Reimbursement of | D35: Eyewear Reimbursement of | E35: Eyewear Reimbursement of | F35: Eyewear Reimbursement of | G35: Eyewear Reimbursement of
B36: $100 per year | C36: $100 per year | D36: $100 per year | E36: $100 per year | F36: $100 per year | G36: $100 per year
A37: Pediatric Dental: Preventative & Routine | B37: Preventive covered at 100%. Routine covered at 80% | C37: Preventive covered at 100%, subject to balance billng. | D37: Preventive covered at 100%. Routine covered at 80% | E37: Preventive covered at 100%, subject to balance billng. | F37: Preventive cleaning and exams not subject to the deductible. Preventive services covered at 100%, subject to the deductible. Routine services covered at 80%, subject to the deductible | G37: Preventive cleaning and exams not subject to the deductible. Preventive services covered at 100%, subject to the deductible. Routine services covered at 80%, subject to the deductible and balance billing
C38: Routine covered at 80%,subject to the deductible and balance billing | E38: Routine covered at 80%,subject to the deductible and balance billing
A39: Plan Overview
A40: Plan ID | B40: 78124NY0980057-01 (GLL3) | D40: 78124NY0980137-01 (GLO5) | F40: 78124NY1000025-01 (GLR7)
A41: Plan Name | B41: SimplyBlue Plus Gold 1 | D41: SimplyBlue Plus Gold 5 | F41: SimplyBlue Plus Gold 6
A42: Aggregation Design | B42: Individual Aggregation | D42: Individual Aggregation | F42: Family Aggregation
A43: Plan Highlights | B43: Predictable out-of-pocket costs without a deductible, includes Active&Fit ExerciseRewards. | D43: Predictable out-of-pocket costs without a deductible, includes Active&Fit ExerciseRewards. | F43: A deductible is applied to all covered medical and prescription drug benefits. Preventive services are covered in full. Plan includes Active&Fit ExerciseRewards.
A44: Plan Type | B44: Copay | D44: Copay | F44: Deductible HSA
A45: HSA Eligible | B45: No | D45: No | F45: Yes
A46: Quote Effective | B46: 01/01/2022 - 03/31/2022 | D46: 01/01/2022 - 03/31/2022 | F46: 01/01/2022 - 03/31/2022
A47: Rate ($) | B47: Small Group | D47: Small Group | F47: Small Group
A48: Plan features
A49: Primary Care Physician (PCP) | B49: Not Required | D49: Not Required | F49: Not Required
A50: Referrals | B50: Not Required | D50: Not Required | F50: Not Required
A51: Out of network benefits | B51: Covered at 80%, subject to the deductible | D51: Covered at 80%, subject to the deductible | F51: Covered at 60%, subject to the deductible
A52: Out of area benefits | B52: Coverage provided worldwide through our BlueCard Network | D52: Coverage provided worldwide through our BlueCard Network | F52: Coverage provided worldwide through our BlueCard Network
...

Sheet Gold 2
B1: SimplyBlue Plus Gold 14 | D1: SimplyBlue Plus Gold 17 | F1: SimplyBlue Plus Gold 18
A2: Single | B2: 673.98 | D2: 671.85 | F2: 654.36
A3: Subscriber & Spouse | B3: 1347.95 | D3: 1343.69 | F3: 1308.72
A4: Subscriber & Child(ren) | B4: 1145.76 | D4: 1142.14 | F4: 1112.41
A5: Family | B5: 1920.84 | D5: 1914.76 | F5: 1864.92
A6: Primary Care Office Visit | B6: $25 copay per visit, subject to deductible | C6: Covered at 60%, subject to the deductible | D6: $30 copay per visit | E6: Covered at 60%, subject to the deductible | F6: $40 copay per visit | G6: Covered at 60%, subject to the deductible
A7: Specialist Office Visit | B7: $40 copay per visit, subject to deductible | C7: Covered at 60%, subject to the deductible | D7: $50 copay per visit | E7: Covered at 60%, subject to the deductible | F7: $60 copay per visit | G7: Covered at 60%, subject to the deductible
A8: Coinsurance | B8: Covered at 80% | C8: Covered at 60% | D8: Covered at 80% | E8: Covered at 60% | F8: Covered at 80% | G8: Covered at 60%
A9: Deductible | B9: In-Network: $1,000 Individual / | C9: Out-of-Network: $5,000 Individual / $10,000 Family | D9: In-Network: $1,000 Individual / | E9: Out-of-Network: $5,000 Individual / $10,000 Family | F9: In-Network: $1,100 Individual / | G9: Out-of-Network: $5,000 Individual / $10,000 Family
B10: $2,000 Family | D10: $2,000 Family | F10: $2,200 Family
A11: Out of pocket maximum | B11: $5,500 Individual / $11,000 Family | C11: $10,000 Individual / $20,000 Family | D11: $8,150 Individual / $16,300 Family | E11: $10,000 Individual / $20,000 Family | F11: $8,250 Individual / $16,500 Family | G11: $10,000 Individual / $20,000 Family
A12: Lifetime maximum | B12: None | C12: None | D12: None | E12: None | F12: None | G12: None
A13: Well child visits | B13: Covered In Full | C13: Covered at 60%, subject to the deductible | D13: Covered In Full | E13: Covered at 60%, subject to the deductible | F13: Covered In Full | G13: Covered at 60%, subject to the deductible
A14: +Adult immunizations | B14: Covered In Full | C14: Covered at 60%, subject to the deductible | D14: Covered In Full | E14: Covered at 60%, subject to the deductible | F14: Covered In Full | G14: Covered at 60%, subject to the deductible
A15: Routine GYN Exam | B15: Covered In Full | C15: Covered at 60%, subject to the deductible | D15: Covered In Full | E15: Covered at 60%, subject to the deductible | F15: Covered In Full | G15: Covered at 60%, subject to the deductible
A16: +Prostate cancer screening | B16: Covered In Full | C16: Covered at 60%, subject to the deductible | D16: Covered In Full | E16: Covered at 60%, subject to the deductible | F16: Covered In Full | G16: Covered at 60%, subject to the deductible
A17: Telemedicine and Telehealth Services | B17: Covered In Full, subject to deductible | C17: Covered at 60%, subject to the deductible | D17: Covered In Full | E17: Covered at 60%, subject to the deductible | F17: Covered In Full | G17: Covered at 60%, subject to the deductible
A18: Diagnostic x-rays | B18: $40 copay per visit, subject to the deductible | C18: Covered at 60%, subject to the deductible | D18: $50 copay per visit | E18: Covered at 60%, subject to the deductible | F18: $60 copay per visit | G18: Covered at 60%, subject to the deductible
A19: Diagnostic laboratory and pathology | B19: $25 copay per visit, subject to the deductible | C19: Covered at 60%, subject to the deductible | D19: $30 copay per visit | E19: Covered at 60%, subject to the deductible | F19: $40 copay per visit | G19: Covered at 60%, subject to the deductible
A20: Chemotherapy | B20: $25 PCP copay per visit, subject to deductible | C20: Covered at 60%, subject to the deductible | D20: $30 copay per visit | E20: Covered at 60%, subject to the deductible | F20: $40 copay per visit | G20: Covered at 60%, subject to the deductible
A21: Radiation therapy | B21: $40 copay per visit, subject to the deductible | C21: Covered at 60%, subject to the deductible | D21: $50 copay per visit | E21: Covered at 60%, subject to the deductible | F21: $60 copay per visit | G21: Covered at 60%, subject to the deductible
A22: Prenatal care | B22: Covered in full (Cost share may apply to ultrasounds, lab work and sick visits) | C22: Covered at 60%, subject to the deductible | D22: Covered in full (Cost share may apply to ultrasounds, lab work and sick visits) | E22: Covered at 60%, subject to the deductible | F22: Covered in full (Cost share may apply to ultrasounds, lab work and sick visits) | G22: Covered at 60%, subject to the deductible
... A39: Adult Eyewear | B39: Eyewear Reimbursement of | C39: Eyewear Reimbursement of | D39: Eyewear Reimbursement of | E39: Eyewear Reimbursement of | F39: Eyewear Reimbursement of | G39: Eyewear Reimbursement of
B40: $100 per year | C40: $100 per year | D40: $100 per year | E40: $100 per year | F40: $100 per year | G40: $100 per year
A41: Pediatric Dental: Preventative & Routine | B41: Preventive covered at 100%. Routine covered at 80%, subject to the deductible | C41: Preventive covered at 100%, subject to balance billing. | D41: Preventive covered at 100%. Routine covered at 80%, subject to the deductible | E41: Preventive covered at 100%, subject to balance billing. | F41: Preventive covered at 100%. Routine covered at 80%, subject to the deductible | G41: Preventive covered at 100%, subject to balance billing.
C42: Routine covered at 80%, | E42: Routine covered at 80%, | G42: Routine covered at 80%,
C43: subject to the deductible and balance billing | E43: subject to the deductible and balance billing | G43: subject to the deductible and balance billing
A44: Plan Overview
A45: Plan ID | B45: 78124NY0990089-01 (GMB3) | D45: 78124NY0990249-01 (GMM5) | F45: 78124NY0990265-01 (GMO1)
A46: Plan Name | B46: SimplyBlue Plus Gold 14 | D46: SimplyBlue Plus Gold 17 | F46: SimplyBlue Plus Gold 18
A47: Aggregation Design | B47: Individual Aggregation | D47: Individual Aggregation | F47: Individual Aggregation
A48: Plan Highlights | B48: A deductible is applied to all covered medical benefits, prescription drugs are not subject to the deductible. Preventive services are covered in full. Plan includes Active&Fit ExerciseRewards. | D48: A deductible is applied to select covered medical benefits, prescription drugs are not subject to the deductible. Preventive services are covered in full, includes Active&Fit ExerciseRewards. | F48: A deductible is applied to select covered medical benefits, prescription drugs are not subject to the deductible. Preventive services are covered in full, includes Active&Fit ExerciseRewards.
A49: Plan Type | B49: Hybrid | D49: Hybrid | F49: Hybrid
A50: HSA Eligible | B50: No | D50: No | F50: No
A51: Quote Effective | B51: 01/01/2022 - 03/31/2022 | D51: 01/01/2022 - 03/31/2022 | F51: 01/01/2022 - 03/31/2022
A52: Rate ($) | B52: Small Group | D52: Small Group | F52: Small Group
A53: Plan features
A54: Primary Care Physician (PCP) | B54: Not Required | D54: Not Required | F54: Not Required
A55: Referrals | B55: Not Required | D55: Not Required | F55: Not Required
A56: Out of network benefits | B56: Covered at 60%, subject to the deductible | D56: Covered at 60%, subject to the deductible | F56: Covered at 60%, subject to the deductible
...

Sheet Standard
B1: SimplyBlue Plus Standard Platinum | D1: SimplyBlue Plus Standard Silver | F1: SimplyBlue Plus Standard Gold | H1: SimplyBlue Plus Standard Bronze HSA
A2: Single | B2: 815.8 | D2: 617.86 | F2: 706.9 | H2: 438.64
A3: Subscriber & Spouse | B3: 1631.59 | D3: 1235.73 | F3: 1413.81 | H3: 877.27
A4: Subscriber & Child(ren) | B4: 1386.86 | D4: 1050.37 | F4: 1201.74 | H4: 745.68
A5: Family | B5: 2325.02 | D5: 1760.92 | F5: 2014.67 | H5: 1250.11
A6: Primary Care Office Visit | B6: $15 copay per visit | C6: Covered at 80%, subject to the deductible | D6: $30 copay per visit, subject to deductible | E6: Covered at 60%, subject to the deductible | F6: $25 copay per visit, subject to deductible | G6: Covered at 60%, subject to the deductible | H6: Covered at 50%, subject to the deductible | I6: Covered at 100%, subject to the deductible
A7: Specialist Office Visit | B7: $35 copay per visit | C7: Covered at 80%, subject to the deductible | D7: $50 copay per visit, subject to deductible | E7: Covered at 60%, subject to the deductible | F7: $40 copay per visit, subject to deductible | G7: Covered at 60%, subject to the deductible | H7: Covered at 50%, subject to the deductible | I7: Covered at 100%, subject to the deductible
A8: Coinsurance | B8: None | C8: Covered at 80% | D8: Covered at 100% | E8: Covered at 60% | F8: Covered at 100% | G8: Covered at 60% | H8: Covered at 50% | I8: Covered at 100%
A9: Deductible | B9: None | C9: Out-of-Network: | D9: In-Network: $1,300 Individual / $2,600 Family | E9: Out-of-Network: | F9: In-Network: $600 Individual / $1,200 Family | G9: Out-of-Network: | H9: In-Network: $6,100 Individual / $12,200 Family | I9: Out-of-Network:
C10: $5,000 Individual / | E10: $5,000 Individual / | G10: $5,000 Individual / | I10: $10,000 Individual /
C11: $10,000 Family | E11: $10,000 Family | G11: $10,000 Family | I11: $20,000 Family
A12: Out of pocket maximum | B12: $2,000 Individual / | C12: $10,000 Individual / | D12: $8,500 Individual / | E12: $10,000 Individual / | F12: $4,000 Individual / | G12: $10,000 Individual / | H12: $6,900 Individual / | I12: $10,000 Individual /
B13: $4,000 Family | C13: $20,000 Family | D13: $17,000 Family | E13: $20,000 Family | F13: $8,000 Family | G13: $20,000 Family | H13: $13,800 Family | I13: $20,000 Family
A14: Well child visits | B14: Covered In Full | C14: Covered at 80%, subject to the deductible | D14: Covered In Full | E14: Covered at 60%, subject to the deductible | F14: Covered In Full | G14: Covered at 60%, subject to the deductible | H14: Covered In Full | I14: Covered at 100%, subject to the deductible
A15: +Adult immunizations | B15: Covered In Full | C15: Covered at 80%, subject to the deductible | D15: Covered In Full | E15: Covered at 60%, subject to the deductible | F15: Covered In Full | G15: Covered at 60%, subject to the deductible | H15: Covered In Full | I15: Covered at 100%, subject to the deductible
A16: Routine GYN Exam | B16: Covered In Full | C16: Covered at 80%, subject to the deductible | D16: Covered In Full | E16: Covered at 60%, subject to the deductible | F16: Covered In Full | G16: Covered at 60%, subject to the deductible | H16: Covered In Full | I16: Covered at 100%, subject to the deductible
A17: +Prostate cancer screening | B17: Covered In Full | C17: Covered at 80%, subject to the deductible | D17: Covered In Full | E17: Covered at 60%, subject to the deductible | F17: Covered In Full | G17: Covered at 60%, subject to the deductible | H17: Covered In Full | I17: Covered at 100%, subject to the deductible
A18: Telemedicine and Telehealth Services | B18: Covered In Full | C18: Covered at 80%, subject to the deductible | D18: Covered In Full | E18: Covered at 60%, subject to the deductible | F18: Covered In Full | G18: Covered at 60%, subject to the deductible | H18: Covered In Full, subject to deductible | I18: Covered at 100%, subject to the deductible
A19: Diagnostic x-rays | B19: $15 PCP copay; $35 Specialist copay per visit | C19: Covered at 80%, subject to the deductible | D19: $30 PCP copay; $75 copay per visit, subject to deductible | E19: Covered at 60%, subject to the deductible | F19: $25 PCP copay; $40 copay per visit, subject to deductible | G19: Covered at 60%, subject to the deductible | H19: Covered at 50%, subject to the deductible | I19: Covered at 100%, subject to the deductible
A20: Diagnostic laboratory and pathology | B20: $15 PCP copay; $35 Specialist copay per visit | C20: Covered at 80%, subject to the deductible | D20: $30 PCP copay; $50 Specialist copay per visit, subject to deductible | E20: Covered at 60%, subject to the deductible | F20: $25 PCP copay; $40 Specialist copay per visit, subject to deductible | G20: Covered at 60%, subject to the deductible | H20: Covered at 50%, subject to the deductible | I20: Covered at 100%, subject to the deductible
A21: Chemotherapy | B21: $15 copay | C21: Covered at 80%, subject to the deductible | D21: $30 PCP copay per visit, subject to deductible | E21: Covered at 60%, subject to the deductible | F21: $25 PCP copay per visit, subject to deductible | G21: Covered at 60%, subject to the deductible | H21: Covered at 50%, subject to the deductible | I21: Covered at 100%, subject to the deductible
A22: Radiation therapy | B22: $15 copay | C22: Covered at 80%, subject to the deductible | D22: $30 PCP copay per visit, subject to deductible | E22: Covered at 60%, subject to the deductible | F22: $25 PCP copay per visit, subject to deductible | G22: Covered at 60%, subject to the deductible | H22: Covered at 50%, subject to the deductible | I22: Covered at 100%, subject to the deductible
A23: Prenatal care | B23: Covered in full (Cost share may apply to ultrasounds, lab work and sick visits) | C23: Covered at 80%, subject to the deductible | D23: Covered in full (Cost share may apply to ultrasounds, lab work and sick visits) | E23: Covered at 60%, subject to the deductible | F23: Covered in full (Cost share may apply to ultrasounds, lab work and sick visits) | G23: Covered at 60%, subject to the deductible | H23: Covered in full (Cost share may apply to ultrasounds, lab work and sick visits) | I23: Covered at 100%, subject to the deductible
A24: Prescription Drug Coverage | B24: $10/$30/$60 | C24: Not Covered | D24: $10/$35/$70 | E24: Not Covered | F24: $10/$35/$70 | G24: Not Covered | H24: $10/$35/$70, subject to the plan deductible | I24: Not Covered
A25: Emergency room care | B25: $100 copay per visit | C25: $100 copay per visit | D25: $300 copay per visit, subject to deductible | E25: $300 copay per visit, subject to deductible | F25: $150 copay per visit, subject to deductible | G25: $150 copay per visit, subject to deductible | H25: Covered at 50%, subject to the deductible | I25: Covered at 50%, subject to the deductible
... A40: Pediatric Dental: Preventative & Routine | B40: $15 per visit | C40: $15 per visit, subject to the deductible and balance billing | D40: $30 per visit, subject to the deductible | E40: $30 per visit, subject to the deductible and balance billing | F40: $25 per visit, subject to the deductible | G40: $25 per visit, subject to the deductible and balance billing | H40: Covered at 50%, subject to the deductible | I40: Covered at 100%, subject to the deductible and balance billing
A41: Plan Overview
A42: Plan ID | B42: 78124NY0980009-01 (GLI1) | D42: 78124NY0990009-01 (GLY1) | F42: 78124NY0990041-01 (GLZ7) | H42: 78124NY1000009-01 (GLQ1)
A43: Plan Name | B43: SimplyBlue Plus Standard Platinum | D43: SimplyBlue Plus Standard Silver | F43: SimplyBlue Plus Standard Gold | H43: SimplyBlue Plus Standard Bronze HSA
A44: Aggregation Design | B44: Individual Aggregation | D44: Individual Aggregation | F44: Individual Aggregation | H44: Individual Aggregation
A45: Plan Highlights | B45: Predictable out-of-pocket costs without a deductible, includes Active&Fit ExerciseRewards. | D45: A deductible is applied to all covered medical benefits, prescription drugs are not subject to the deductible. Preventive services are covered in full. Plan includes Active&Fit ExerciseRewards. | F45: A deductible is applied to all covered medical benefits, prescription drugs are not subject to the deductible. Preventive services are covered in full. Plan includes Active&Fit ExerciseRewards. | H45: A deductible is applied to all covered medical and prescription drug benefits. Preventive services are covered in full. Plan includes Active&Fit ExerciseRewards.
A46: Plan Type | B46: Copay | D46: Hybrid | F46: Hybrid | H46: Deductible HSA
A47: HSA Eligible | B47: No | D47: No | F47: No | H47: Yes
A48: Quote Effective | B48: 01/01/2022 - 03/31/2022 | D48: 01/01/2022 - 03/31/2022 | F48: 01/01/2022 - 03/31/2022 | H48: 01/01/2022 - 03/31/2022
A49: Rate ($) | B49: Small Group | D49: Small Group | F49: Small Group | H49: Small Group
A50: Plan features
A51: Primary Care Physician (PCP) | B51: Not Required | D51: Not Required | F51: Not Required | H51: Not Required
A52: Referrals | B52: Not Required | D52: Not Required | F52: Not Required | H52: Not Required
A53: Out of network benefits | B53: Covered at 80%, subject to the deductible | D53: Covered at 60%, subject to the deductible | F53: Covered at 60%, subject to the deductible | H53: Covered at 100%, subject to the deductible
A54: Out of area benefits | B54: Coverage provided worldwide through our BlueCard Network | D54: Coverage provided worldwide through our BlueCard Network | F54: Coverage provided worldwide through our BlueCard Network | H54: Coverage provided worldwide through our BlueCard Network
...

Sheet Bronze Options
B1: SimplyBlue Plus Standard Bronze HSA | D1: SimplyBlue Plus Bronze 3 | F1: SimplyBlue Plus Bronze 4 | H1: SimplyBlue Plus Bronze 5
A2: Plan Overview
A3: Plan ID | B3: 78124NY1000009-00 (SXU3) | D3: 78124NY1000153-00 (SXZ1) | F3: 78124NY1000169-00 (SYA7) | H3: 78124NY1000201-00 (SYN5)
A4: Plan Name | B4: SimplyBlue Plus Standard Bronze HSA | D4: SimplyBlue Plus Bronze 3 | F4: SimplyBlue Plus Bronze 4 | H4: SimplyBlue Plus Bronze 5
A5: Aggregation Design | B5: Individual Aggregation | D5: Family Aggregation | F5: Family Aggregation | H5: Family Aggregation
A6: Plan Highlights | B6: A deductible is applied to all covered medical and prescription drug benefits. Preventive services are covered in full. Plan includes Active&Fit ExerciseRewards. | D6: A deductible is applied to all covered medical and prescription drug benefits. Preventive services are covered in full. Plan includes Active&Fit ExerciseRewards. | F6: A deductible is applied to all covered medical and prescription drug benefits. Preventive services are covered in full. Plan includes Active&Fit ExerciseRewards. | H6: A deductible is applied to all covered medical and prescription drug benefits. Preventive services are covered in full. Plan includes Active&Fit ExerciseRewards.
A7: Plan Type | B7: Deductible HSA | D7: Deductible HSA | F7: Deductible HSA | H7: Deductible HSA
A8: HSA Eligible | B8: Yes | D8: Yes | F8: Yes | H8: Yes
A9: Quote Effective | B9: 01/01/2022 - 03/31/2022 | D9: 01/01/2022 - 03/31/2022 | F9: 01/01/2022 - 03/31/2022 | H9: 01/01/2022 - 03/31/2022
A10: Rate ($) | B10: Small Group | D10: Small Group | F10: Small Group | H10: Small Group
A11: Single | B11: 438.64 | D11: 438.68 | F11: 438.93 | H11: 439.44
A12: Subscriber & Spouse | B12: 877.27 | D12: 877.35 | F12: 877.87 | H12: 878.88
A13: Subscriber & Child(ren) | B13: 745.68 | D13: 745.75 | F13: 746.19 | H13: 747.05
A14: Family | B14: 1250.11 | D14: 1250.22 | F14: 1250.96 | H14: 1252.4
A15: Plan features
A16: Primary Care Physician (PCP) | B16: Not Required | D16: Not Required | F16: Not Required | H16: Not Required
A17: Referrals | B17: Not Required | D17: Not Required | F17: Not Required | H17: Not Required
A18: Out of network benefits | B18: Covered at 100%, subject to the deductible | D18: Covered at 100%, subject to the deductible | F18: Covered at 100%, subject to the deductible | H18: Covered at 100%, subject to the deductible
A19: Out of area benefits | B19: Coverage provided worldwide through our BlueCard Network | D19: Coverage provided worldwide through our BlueCard Network | F19: Coverage provided worldwide through our BlueCard Network | H19: Coverage provided worldwide through our BlueCard Network
A20: Student/Dependent coverage | B20: Qualified dependents are covered to age 26 | D20: Qualified dependents are covered to age 26 | F20: Qualified dependents are covered to age 26 | H20: Qualified dependents are covered to age 26
A21: Domestic partner | B21: Covered | D21: Covered | F21: Covered | H21: Covered
A22: Wellness Incentives | B22: Active&Fit ExerciseRewards receive up to | D22: Active&Fit ExerciseRewards receive up to | F22: Active&Fit ExerciseRewards receive up to | H22: Active&Fit ExerciseRewards receive up to
B23: $600 in rewards a year by visiting a qualified fitness facility or by tracking your steps using a wearable device. Save on Gym memberships | D23: $600 in rewards a year by visiting a qualified fitness facility or by tracking your steps using a wearable device. Save on Gym memberships | F23: $600 in rewards a year by visiting a qualified fitness facility or by tracking your steps using a wearable device. Save on Gym memberships | H23: $600 in rewards a year by visiting a qualified fitness facility or by tracking your steps using a wearable device. Save on Gym memberships
B24: with Active&Fit Direct. | D24: with Active&Fit Direct. | F24: with Active&Fit Direct. | H24: with Active&Fit Direct.
A25: Plan cost-sharing highlights
A26: Plan cost-sharing highlights | B26: In-Network | C26: Out-of-Network | D26: In-Network | E26: Out-of-Network | F26: In-Network | G26: Out-of-Network | H26: In-Network | I26: Out-of-Network
A27: Primary Care Office Visit | B27: Covered at 50%, subject to the deductible | C27: Covered at 100%, subject to the deductible | D27: Covered at 50%, subject to the deductible | E27: Covered at 100%, subject to the deductible | F27: Covered at 100%, subject to the deductible | G27: Covered at 100%, subject to the deductible | H27: $40 copay per visit, subject to deductible | I27: Covered at 100%, subject to the deductible
A28: Specialist Office Visit | B28: Covered at 50%, subject to the deductible | C28: Covered at 100%, subject to the deductible | D28: Covered at 50%, subject to the deductible | E28: Covered at 100%, subject to the deductible | F28: Covered at 100%, subject to the deductible | G28: Covered at 100%, subject to the deductible | H28: $60 copay per visit, subject to deductible | I28: Covered at 100%, subject to the deductible
A29: Coinsurance | B29: Covered at 50% | C29: Covered at 100% | D29: Covered at 50% | E29: Covered at 100% | F29: Covered at 100% | G29: Covered at 100% | H29: Covered at 100% | I29: Covered at 100%
A30: Deductible | B30: In-Network: $6,100 Individual / $12,200 Family | C30: Out-of-Network: | D30: In-Network: $5,500 Individual / $11,000 Family | E30: Out-of-Network: | F30: In-Network: $7,000 Individual / $14,000 Family | G30: Out-of-Network: | H30: In-Network: $6,000 Individual / $12,000 Family | I30: Out-of-Network:
C31: $10,000 Individual / | E31: $10,000 Individual / | G31: $10,000 Individual / | I31: $10,000 Individual /
C32: $20,000 Family | E32: $20,000 Family | G32: $20,000 Family | I32: $20,000 Family
A33: Out of pocket maximum | B33: $6,900 Individual / | C33: $10,000 Individual / | D33: $7,000 Individual / | E33: $10,000 Individual / | F33: $7,000 Individual / | G33: $10,000 Individual / | H33: $7,000 Individual / | I33: $10,000 Individual /
B34: $13,800 Family | C34: $20,000 Family | D34: $14,000 Family | E34: $20,000 Family | F34: $14,000 Family | G34: $20,000 Family | H34: $14,000 Family | I34: $20,000 Family
A35: Lifetime maximum | B35: None | C35: None | D35: None | E35: None | F35: None | G35: None | H35: None | I35: None
A36: Plan Benefits
A37: Preventive Healthcare Services | B37: In-Network | C37: Out-of-Network | D37: In-Network | E37: Out-of-Network | F37: In-Network | G37: Out-of-Network | H37: In-Network | I37: Out-of-Network
A38: Well child visits | B38: Covered In Full | C38: Covered at 100%, subject to the deductible | D38: Covered In Full | E38: Covered at 100%, subject to the deductible | F38: Covered In Full | G38: Covered at 100%, subject to the deductible | H38: Covered In Full | I38: Covered at 100%, subject to the deductible
A39: Adult routine physical exams | B39: Covered In Full | C39: Covered at 100%, subject to the deductible | D39: Covered In Full | E39: Covered at 100%, subject to the deductible | F39: Covered In Full | G39: Covered at 100%, subject to the deductible | H39: Covered In Full | I39: Covered at 100%, subject to the deductible
A40: +Adult immunizations | B40: Covered In Full | C40: Covered at 100%, subject to the deductible | D40: Covered In Full | E40: Covered at 100%, subject to the deductible | F40: Covered In Full | G40: Covered at 100%, subject to the deductible | H40: Covered In Full | I40: Covered at 100%, subject to the deductible
...

Sheet Plat 2
B1: SimplyBlue Plus Standard Platinum | D1: SimplyBlue Plus Platinum 6
A2: Single | B2: 815.8 | D2: 795.26
A3: Subscriber & Spouse | B3: 1631.59 | D3: 1590.52
A4: Subscriber & Child(ren) | B4: 1386.86 | D4: 1351.94
A5: Family | B5: 2325.02 | D5: 2266.49
A6: Primary Care Office Visit | B6: $15 copay per visit | C6: Covered at 80%, subject to the deductible | D6: $30 copay per visit | E6: Covered at 80%, subject to the deductible
A7: Specialist Office Visit | B7: $35 copay per visit | C7: Covered at 80%, subject to the deductible | D7: $50 copay per visit | E7: Covered at 80%, subject to the deductible
A8: Coinsurance | B8: None | C8: Covered at 80% | D8: None | E8: Covered at 80%
A9: Deductible | B9: None | C9: Out-of-Network: $5,000 Individual / $10,000 Family | D9: None | E9: Out-of-Network: $5,000 Individual / $10,000 Family
A10: Out of pocket maximum | B10: $2,000 Individual / $4,000 Family | C10: $10,000 Individual / $20,000 Family | D10: $6,550 Individual / $13,100 Family | E10: $10,000 Individual / $20,000 Family
A11: Lifetime maximum | B11: None | C11: None | D11: None | E11: None
A12: Well child visits | B12: Covered In Full | C12: Covered at 80%, subject to the deductible | D12: Covered In Full | E12: Covered at 80%, subject to the deductible
A13: +Adult immunizations | B13: Covered In Full | C13: Covered at 80%, subject to the deductible | D13: Covered In Full | E13: Covered at 80%, subject to the deductible
A14: Routine GYN Exam | B14: Covered In Full | C14: Covered at 80%, subject to the deductible | D14: Covered In Full | E14: Covered at 80%, subject to the deductible
A15: +Prostate cancer screening | B15: Covered In Full | C15: Covered at 80%, subject to the deductible | D15: Covered In Full | E15: Covered at 80%, subject to the deductible
A16: Telemedicine and Telehealth Services | B16: Covered In Full | C16: Covered at 80%, subject to the deductible | D16: Covered In Full | E16: Covered at 80%, subject to the deductible
A17: Diagnostic x-rays | B17: $15 PCP copay; $35 Specialist copay per visit | C17: Covered at 80%, subject to the deductible | D17: $50 copay per visit | E17: Covered at 80%, subject to the deductible
... A31: Outpatient mental health care | B31: $15 copay per visit | C31: Covered at 80%, subject to the deductible | D31: 3 visits covered in full. Next visits covered at | E31: Covered at 80%, subject to the deductible
D32: $30 copay per visit
A33: Inpatient substance use | B33: Subject to $500 copay per admission for unlimited days | C33: Covered at 80%, per admission for unlimited days, subject to the deductible | D33: Subject to $750 copay per admission for unlimited days | E33: Covered at 80%, per admission for unlimited days, subject to the deductible
A34: Outpatient substance use | B34: $15 copay per visit | C34: Covered at 80%, subject to the deductible | D34: 3 visits covered in full. Next visits covered at | E34: Covered at 80%, subject to the deductible
D35: $30 copay per visit
A36: Outpatient therapy | B36: $25 per visit for physical, speech and occupational therapy for up to 60 visits per contract year | C36: Covered at 80%, subject to the deductible for physical, speech and occupational therapy for up to 60 visits per contract year | D36: $50 per visit for physical, speech and occupational therapy for up to 60 visits per contract year | E36: Covered at 80%, subject to the deductible for physical, speech and occupational therapy for up to 60 visits per contract year
A37: Durable medical equipment | B37: Covered at 90% | C37: Covered at 80%, subject to the deductible | D37: Covered at 50% | E37: Covered at 50%, subject to the deductible
A38: Chiropractic | B38: $35 copay | C38: Covered at 80%, subject to the deductible | D38: $30 copay per visit | E38: Covered at 80%, subject to the deductible
A39: Adult Routine Vision Exam | B39: Not Covered | C39: Not Covered | D39: One routine exam covered in full per year | E39: Covered at 80% for one routine exam every year, subject to the deductible
A40: Adult Eyewear | B40: Not Covered | C40: Not Covered | D40: Eyewear Reimbursement of $100 per year | E40: Eyewear Reimbursement of $100 per year
A41: Pediatric Dental: Preventative & Routine | B41: $15 per visit | C41: $15 per visit, subject to the deductible and balance billing | D41: Preventive covered at 100%. Routine covered at 80% | E41: Preventive covered at 100%, subject to balance billng. Routine covered at 80%,subject to the deductible and balance billing
A42: Plan Overview
A43: Plan ID | B43: 78124NY0980009-00 (SXM3) | D43: 78124NY0980185-00 (SYV5)
A44: Plan Name | B44: SimplyBlue Plus Standard Platinum | D44: SimplyBlue Plus Platinum 6
A45: Aggregation Design | B45: Individual Aggregation | D45: Individual Aggregation
A46: Plan Highlights | B46: Predictable out-of-pocket costs without a deductible, includes Active&Fit ExerciseRewards. | D46: Predictable out-of-pocket costs without a deductible, includes Active&Fit ExerciseRewards.
A47: Plan Type | B47: Copay | D47: Copay
A48: HSA Eligible | B48: No | D48: No
A49: Quote Effective | B49: 01/01/2022 - 03/31/2022 | D49: 01/01/2022 - 03/31/2022
A50: Rate ($) | B50: Small Group | D50: Small Group
A51: Plan features
A52: Primary Care Physician (PCP) | B52: Not Required | D52: Not Required
A53: Referrals | B53: Not Required | D53: Not Required
...

Sheet Silver 1
B1: SimplyBlue Plus Silver 6 | D1: SimplyBlue Plus Silver 2 | F1: SimplyBlue Plus Silver 19
A2: Single | B2: 555.42 | D2: 557.23 | F2: 562.09
A3: Subscriber & Spouse | B3: 1110.84 | D3: 1114.47 | F3: 1124.18
A4: Subscriber & Child(ren) | B4: 944.22 | D4: 947.3 | F4: 955.56
A5: Family | B5: 1582.95 | D5: 1588.11 | F5: 1601.96
A6: Primary Care Office Visit | B6: $40 copay per visit, subject to deductible | C6: Covered at 50%, subject to the deductible | D6: Covered at 80%, subject to the deductible | E6: Covered at 60%, subject to the deductible | F6: $25 copay per visit, subject to deductible | G6: Covered at 60%, subject to the deductible
A7: Specialist Office Visit | B7: $60 copay per visit, subject to deductible | C7: Covered at 50%, subject to the deductible | D7: Covered at 80%, subject to the deductible | E7: Covered at 60%, subject to the deductible | F7: $50 copay per visit, subject to deductible | G7: Covered at 60%, subject to the deductible
A8: Coinsurance | B8: Covered at 75% | C8: Covered at 50% | D8: Covered at 80% | E8: Covered at 60% | F8: Covered at 100% | G8: Covered at 60%
A9: Deductible | B9: In-Network: $2,500 Individual / | C9: Out-of-Network: $5,000 Individual / $10,000 Family | D9: In-Network: $2,600 Individual / | E9: Out-of-Network: $5,000 Individual / $10,000 Family | F9: In-Network: $2,500 Individual / | G9: Out-of-Network: $5,000 Individual / $10,000 Family
B10: $5,000 Family | D10: $5,200 Family | F10: $5,000 Family
A11: Out of pocket maximum | B11: $8,000 Individual / $16,000 Family | C11: $10,000 Individual / $20,000 Family | D11: $7,000 Individual / $14,000 Family | E11: $10,000 Individual / $20,000 Family | F11: $6,750 Individual / $13,500 Family | G11: $10,000 Individual / $20,000 Family
A12: Well child visits | B12: Covered In Full | C12: Covered at 50%, subject to the deductible | D12: Covered In Full | E12: Covered at 60%, subject to the deductible | F12: Covered In Full | G12: Covered at 60%, subject to the deductible
A13: Routine GYN Exam | B13: Covered In Full | C13: Covered at 50%, subject to the deductible | D13: Covered In Full | E13: Covered at 60%, subject to the deductible | F13: Covered In Full | G13: Covered at 60%, subject to the deductible
A14: +Prostate cancer screening | B14: Covered In Full | C14: Covered at 50%, subject to the deductible | D14: Covered In Full | E14: Covered at 60%, subject to the deductible | F14: Covered In Full | G14: Covered at 60%, subject to the deductible
A15: Telemedicine and Telehealth Services | B15: Covered In Full, subject to deductible | C15: Covered at 50%, subject to the deductible | D15: Covered In Full, subject to deductible | E15: Covered at 60%, subject to the deductible | F15: Covered In Full, subject to deductible | G15: Covered at 60%, subject to the deductible
A16: Diagnostic x-rays | B16: $60 copay per visit, subject to the deductible | C16: Covered at 50%, subject to the deductible | D16: Covered at 80%, subject to the deductible | E16: Covered at 60%, subject to the deductible | F16: $50 copay per visit, subject to deductible | G16: Covered at 60%, subject to the deductible
A17: Diagnostic laboratory and pathology | B17: $40 copay per visit, subject to the deductible | C17: Covered at 50%, subject to the deductible | D17: Covered at 80%, subject to the deductible | E17: Covered at 60%, subject to the deductible | F17: $25 copay per visit, subject to deductible | G17: Covered at 60%, subject to the deductible
A18: Chemotherapy | B18: $40 PCP copay per visit, subject to deductible | C18: Covered at 50%, subject to the deductible | D18: Covered at 80%, subject to the deductible | E18: Covered at 60%, subject to the deductible | F18: $25 PCP copay per visit, subject to deductible | G18: Covered at 60%, subject to the deductible
A19: Radiation therapy | B19: $60 copay per visit, subject to the deductible | C19: Covered at 50%, subject to the deductible | D19: Covered at 80%, subject to the deductible | E19: Covered at 60%, subject to the deductible | F19: $50 PCP copay per visit, subject to deductible | G19: Covered at 60%, subject to the deductible
A20: Prenatal care | B20: Covered in full (Cost share may apply to ultrasounds, lab work and sick visits) | C20: Covered at 50%, subject to the deductible | D20: Covered in full (Cost share may apply to ultrasounds, lab work and sick visits) | E20: Covered at 60%, subject to the deductible | F20: Covered in full (Cost share may apply to ultrasounds, lab work and sick visits) | G20: Covered at 60%, subject to the deductible
A21: Prescription Drug Coverage | B21: $5/$45/$90 | C21: Not Covered | D21: $5/$45/$90, subject to the plan deductible. Preventive drugs are not subject to the deductible; they are subject to the applicable copay or coinsurance. | E21: Not Covered | F21: $5/$45/$90, subject to the plan deductible. Preventive drugs are not subject to the deductible; they are subject to the applicable copay or coinsurance. | G21: Not Covered
A22: Emergency room care | B22: $350 copay per visit, subject to deductible | C22: $350 copay per visit, subject to deductible | D22: Covered at 80%, subject to the deductible | E22: Covered at 80%, subject to the deductible | F22: $300 copay per visit, subject to deductible | G22: $300 copay per visit, subject to deductible
... A37: Adult Eyewear | B37: Eyewear Reimbursement of | C37: Eyewear Reimbursement of | D37: Eyewear Reimbursement of | E37: Eyewear Reimbursement of | F37: Eyewear Reimbursement of | G37: Eyewear Reimbursement of
B38: $100 per year | C38: $100 per year | D38: $100 per year | E38: $100 per year | F38: $100 per year | G38: $100 per year
A39: Pediatric Dental: Preventative & Routine | B39: Preventive covered at 100%. Routine covered at 80%, subject to the deductible | C39: Preventive covered at 100%, subject to balance billing. | D39: Preventive cleaning and exams not subject to the deductible. Preventive services covered at 100%, subject to the deductible. Routine services covered at 80%, subject to the deductible | E39: Preventive cleaning and exams not subject to the deductible. Preventive services covered at 100%, subject to the deductible. Routine services covered at 80%, subject to the deductible and balance billing | F39: Preventive cleaning and exams not subject to the deductible. Preventive services covered at 100%, subject to the deductible. Routine services covered at 80%, subject to the deductible | G39: Preventive cleaning and exams not subject to the deductible. Preventive services covered at 100%, subject to the deductible. Routine services covered at 80%, subject to the deductible and balance billing
C40: Routine covered at 80%, subject to the deductible and balance billing
A41: Plan Overview
A42: Plan ID | B42: 78124NY0990105-01 (GMC9) | D42: 78124NY1000057-01 (GLT3) | F42: 78124NY1000297-01 (GMZ3)
A43: Plan Name | B43: SimplyBlue Plus Silver 6 | D43: SimplyBlue Plus Silver 2 | F43: SimplyBlue Plus Silver 19
A44: Aggregation Design | B44: Individual Aggregation | D44: Family Aggregation | F44: Family Aggregation
A45: Plan Highlights | B45: A deductible is applied to all covered medical benefits, prescription drugs are not subject to the deductible. Preventive services are covered in full. Plan includes Active&Fit ExerciseRewards. | D45: A deductible is applied to all covered medical and prescription drug benefits. Preventive services are covered in full. Plan includes Active&Fit ExerciseRewards. | F45: A deductible is applied to all covered medical and prescription drug benefits. Preventive services are covered in full. Plan includes Active&Fit ExerciseRewards.
A46: Plan Type | B46: Hybrid | D46: Deductible HSA | F46: Deductible HSA
A47: HSA Eligible | B47: No | D47: Yes | F47: Yes
A48: Quote Effective | B48: 01/01/2022 - 03/31/2022 | D48: 01/01/2022 - 03/31/2022 | F48: 01/01/2022 - 03/31/2022
A49: Rate ($) | B49: Small Group | D49: Small Group | F49: Small Group
A50: Plan features
A51: Primary Care Physician (PCP) | B51: Not Required | D51: Not Required | F51: Not Required
A52: Referrals | B52: Not Required | D52: Not Required | F52: Not Required
A53: Out of network benefits | B53: Covered at 50%, subject to the deductible | D53: Covered at 60%, subject to the deductible | F53: Covered at 60%, subject to the deductible
A54: Out of area benefits | B54: Coverage provided worldwide through our BlueCard Network | D54: Coverage provided worldwide through our BlueCard Network | F54: Coverage provided worldwide through our BlueCard Network
...

Sheet Healthy NY
B1: Healthy New York EPO | D1: Healthy New York EPO
A2: Plan Overview
A3: Plan ID | B3: 78124NY1110009-00 | D3: 78124NY1110009-00 (SYI7)
A4: Plan Name | B4: Healthy New York EPO | D4: Healthy New York EPO
A5: Aggregation Design | B5: Individual Aggregation | D5: Individual Aggregation
A6: Plan Highlights | B6: A deductible is applied to all covered medical benefits, prescription drugs are not subject to the deductible. Preventive services are covered in full. Plan includes ExerciseRewards. | D6: A deductible is applied to all covered medical benefits, prescription drugs are not subject to the deductible. Preventive services are covered in full. Plan includes Active&Fit ExerciseRewards.
A7: Plan Type | B7: Hybrid | D7: Hybrid
A8: HSA Eligible | B8: No | D8: No
A9: Quote Effective | B9: 01/01/2021 - 03/31/2021 | D9: 01/01/2022 - 03/31/2022
A10: Rate ($) | B10: Small Group | D10: Small Group
A11: Single | B11: 360.93 | D11: 392.94
A12: Subscriber & Spouse | B12: 721.86 | D12: 785.88
A13: Subscriber & Child(ren) | B13: 613.58 | D13: 668
A14: Family | B14: 1028.66 | D14: 1119.89
A15: Plan features
A16: Primary Care Physician (PCP) | B16: Not Required | D16: Not Required
A17: Referrals | B17: Not Required | D17: Not Required
A18: Out of network benefits | B18: Not Covered | D18: Not Covered
A19: Out of area benefits | B19: Coverage provided worldwide through our BlueCardÂ® Network | D19: Coverage provided worldwide through our BlueCard Network
A20: Student/Dependent coverage | B20: Qualified dependents are covered to age 26 | D20: Qualified dependents are covered to age 26
A21: Domestic partner | B21: Covered | D21: Covered
A22: Wellness Incentives | B22: ExerciseRewardsÃ‚Â® receive up to $600 in rewards a year by visiting a qualified fitness facility and save on Gym memberships with Active&Fit DirectÃ¢â€žÂ¢. | D22: Active&Fit ExerciseRewards receive up to $600 in rewards a year by visiting a qualified fitness facility or by tracking your steps using a wearable device. Save on Gym memberships with Active&Fit Direct.
A23: Plan cost-sharing highlights
A24: Plan cost-sharing highlights | B24: In-Network | C24: Out-of-Network | D24: In-Network | E24: Out-of-Network
A25: Primary Care Office Visit | B25: $25 copay per visit, subject to deductible | C25: Not Covered | D25: $25 copay per visit, subject to deductible | E25: Not Covered
A26: Specialist Office Visit | B26: $40 copay per visit, subject to deductible | C26: Not Covered | D26: $40 copay per visit, subject to deductible | E26: Not Covered
A27: Coinsurance | B27: Covered at 100% | C27: Not Covered | D27: Covered at 100% | E27: Not Covered
A28: Deductible | B28: In-Network: $600 Individual / $1,200 Family | C28: Not Covered | D28: In-Network: $600 Individual / $1,200 Family | E28: Not Covered
A29: Out of pocket maximum | B29: In-Network: $4,000 Individual / $8,000 Family | C29: Not Covered | D29: $4,000 Individual / $8,000 Family | E29: Not Covered
A30: Lifetime maximum | B30: None | C30: None | D30: None | E30: None
A31: Plan Benefits
A32: Preventive Healthcare Services | B32: In-Network | C32: Out-of-Network | D32: In-Network | E32: Out-of-Network
A33: Well child visits | B33: Covered In Full | C33: Not Covered | D33: Covered In Full | E33: Not Covered
A34: Adult routine physical exams | B34: Covered In Full | C34: Not Covered | D34: Covered In Full | E34: Not Covered
A35: +Adult immunizations | B35: Covered In Full | C35: Not Covered | D35: Covered In Full | E35: Not Covered
A36: +Mammography | B36: Covered In Full | C36: Not Covered | D36: Covered In Full | E36: Not Covered
A37: +Pap smear | B37: Covered In Full | C37: Not Covered | D37: Covered In Full | E37: Not Covered
A38: Routine GYN Exam | B38: Covered In Full | C38: Not Covered | D38: Covered In Full | E38: Not Covered
A39: +Prostate cancer screening | B39: Covered In Full | C39: Not Covered | D39: Covered In Full | E39: Not Covered
A40: +Colonoscopy | B40: Preventive screenings covered in full | C40: Not Covered | D40: Preventive screenings covered in full | E40: Not Covered
...

Sheet Silver 2
B1: SimplyBlue Plus Silver 18 | D1: SimplyBlue Plus Silver 14 | F1: SimplyBlue Plus Silver 16 | H1: SimplyBlue Plus Silver 17
A2: Single | B2: 462.05 | D2: 550.27 | F2: 546.37 | H2: 521.23
A3: Subscriber & Spouse | B3: 924.1 | D3: 1100.55 | F3: 1092.74 | H3: 1042.46
A4: Subscriber & Child(ren) | B4: 785.49 | D4: 935.46 | F4: 928.82 | H4: 886.09
A5: Family | B5: 1316.84 | D5: 1568.29 | F5: 1557.16 | H5: 1485.51
A6: Primary Care Office Visit | B6: $50 copay per visit | C6: Covered at 100%, subject to the deductible | D6: Covered at 80%, subject to the deductible | E6: Covered at 60%, subject to the deductible | F6: Covered at 80%, subject to the deductible | G6: Covered at 60%, subject to the deductible | H6: Covered at 80%, subject to the deductible | I6: Covered at 60%, subject to the deductible
A7: Specialist Office Visit | B7: $75 copay per visit | C7: Covered at 100%, subject to the deductible | D7: Covered at 80%, subject to the deductible | E7: Covered at 60%, subject to the deductible | F7: Covered at 80%, subject to the deductible | G7: Covered at 60%, subject to the deductible | H7: Covered at 80%, subject to the deductible | I7: Covered at 60%, subject to the deductible
A8: Coinsurance | B8: Covered at 70% | C8: Covered at 100% | D8: Covered at 80% | E8: Covered at 60% | F8: Covered at 80% | G8: Covered at 60% | H8: Covered at 80% | I8: Covered at 60%
A9: Deductible | B9: In-Network: $7,500 Individual / $15,000 Family | C9: Out-of-Network: | D9: In-Network: $2,800 Individual / $5,600 Family | E9: Out-of-Network: | F9: In-Network: $3,200 Individual / $6,400 Family | G9: Out-of-Network: | H9: In-Network: $3,600 Individual / $7,200 Family | I9: Out-of-Network:
C10: $10,000 Individual / | E10: $5,000 Individual / | G10: $5,000 Individual / | I10: $5,000 Individual /
C11: $20,000 Family | E11: $10,000 Family | G11: $10,000 Family | I11: $10,000 Family
A12: Out of pocket maximum | B12: $8,250 Individual / | C12: $10,000 Individual / | D12: $6,550 Individual / | E12: $10,000 Individual / | F12: $6,550 Individual / | G12: $10,000 Individual / | H12: $6,550 Individual / | I12: $10,000 Individual /
B13: $16,500 Family | C13: $20,000 Family | D13: $13,100 Family | E13: $20,000 Family | F13: $13,100 Family | G13: $20,000 Family | H13: $13,100 Family | I13: $20,000 Family
A14: Adult routine physical exams | B14: Covered In Full | C14: Covered at 100%, subject to the deductible | D14: Covered In Full | E14: Covered at 60%, subject to the deductible | F14: Covered In Full | G14: Covered at 60%, subject to the deductible | H14: Covered In Full | I14: Covered at 60%, subject to the deductible
A15: Routine GYN Exam | B15: Covered In Full | C15: Covered at 100%, subject to the deductible | D15: Covered In Full | E15: Covered at 60%, subject to the deductible | F15: Covered In Full | G15: Covered at 60%, subject to the deductible | H15: Covered In Full | I15: Covered at 60%, subject to the deductible
A16: +Prostate cancer screening | B16: Covered In Full | C16: Covered at 100%, subject to the deductible | D16: Covered In Full | E16: Covered at 60%, subject to the deductible | F16: Covered In Full | G16: Covered at 60%, subject to the deductible | H16: Covered In Full | I16: Covered at 60%, subject to the deductible
A17: Telemedicine and Telehealth Services | B17: Covered In Full | C17: Covered at 100%, subject to the deductible | D17: Covered In Full, subject to deductible | E17: Covered at 60%, subject to the deductible | F17: Covered In Full, subject to deductible | G17: Covered at 60%, subject to the deductible | H17: Covered In Full, subject to deductible | I17: Covered at 60%, subject to the deductible
A18: Diagnostic x-rays | B18: $75 copay per visit | C18: Covered at 100%, subject to the deductible | D18: Covered at 80%, subject to the deductible | E18: Covered at 60%, subject to the deductible | F18: Covered at 80%, subject to the deductible | G18: Covered at 60%, subject to the deductible | H18: Covered at 80%, subject to the deductible | I18: Covered at 60%, subject to the deductible
A19: Diagnostic laboratory and pathology | B19: $50 copay per visit | C19: Covered at 100%, subject to the deductible | D19: Covered at 80%, subject to the deductible | E19: Covered at 60%, subject to the deductible | F19: Covered at 80%, subject to the deductible | G19: Covered at 60%, subject to the deductible | H19: Covered at 80%, subject to the deductible | I19: Covered at 60%, subject to the deductible
A20: Chemotherapy | B20: $50 copay per visit | C20: Covered at 100%, subject to the deductible | D20: Covered at 80%, subject to the deductible | E20: Covered at 60%, subject to the deductible | F20: Covered at 80%, subject to the deductible | G20: Covered at 60%, subject to the deductible | H20: Covered at 80%, subject to the deductible | I20: Covered at 60%, subject to the deductible
A21: Radiation therapy | B21: $75 copay per visit | C21: Covered at 100%, subject to the deductible | D21: Covered at 80%, subject to the deductible | E21: Covered at 60%, subject to the deductible | F21: Covered at 80%, subject to the deductible | G21: Covered at 60%, subject to the deductible | H21: Covered at 80%, subject to the deductible | I21: Covered at 60%, subject to the deductible
A22: Prenatal care | B22: Covered in full (Cost share may apply to ultrasounds, lab work and sick visits) | C22: Covered at 100%, subject to the deductible | D22: Covered in full (Cost share may apply to ultrasounds, lab work and sick visits) | E22: Covered at 60%, subject to the deductible | F22: Covered in full (Cost share may apply to ultrasounds, lab work and sick visits) | G22: Covered at 60%, subject to the deductible | H22: Covered in full (Cost share may apply to ultrasounds, lab work and sick visits) | I22: Covered at 60%, subject to the deductible
A23: Prescription Drug Coverage | B23: $10/40%/50% | C23: Not Covered | D23: $5/$45/$90, subject to the plan deductible. | E23: Not Covered | F23: $5/$45/$90, subject to the plan deductible. | G23: Not Covered | H23: $5/$35/$70, subject to the plan deductible. | I23: Not Covered
D24: Preventive drugs are not subject to the | F24: Preventive drugs are not subject to the | H24: Preventive drugs are not subject to the
A25: Emergency room care | B25: $650 copay per visit | C25: $650 copay per visit | D25: Covered at 80%, subject to the deductible | E25: Covered at 80%, subject to the deductible | F25: Covered at 80%, subject to the deductible | G25: Covered at 80%, subject to the deductible | H25: Covered at 80%, subject to the deductible | I25: Covered at 80%, subject to the deductible
A26: Freestanding urgent care center | B26: $75 copay per visit | C26: Covered at 100%, subject to the deductible | D26: Covered at 80%, subject to the deductible | E26: Covered at 60%, subject to the deductible | F26: Covered at 80%, subject to the deductible | G26: Covered at 60%, subject to the deductible | H26: Covered at 80%, subject to the deductible | I26: Covered at 60%, subject to the deductible
A27: Ambulance | B27: $650 copay per visit | C27: $650 copay per visit | D27: Covered at 80%, subject to the deductible | E27: Covered at 80%, subject to the deductible | F27: Covered at 80%, subject to the deductible | G27: Covered at 80%, subject to the deductible | H27: Covered at 80%, subject to the deductible | I27: Covered at 80%, subject to the deductible
A28: Diagnostic laboratory and pathology | B28: $50 copay per visit | C28: Covered at 100%, subject to the | D28: Covered at 80%, subject to the | E28: Covered at 60%, subject to the | F28: Covered at 80%, subject to the | G28: Covered at 60%, subject to the | H28: Covered at 80%, subject to the | I28: Covered at 60%, subject to the
C29: deductible | D29: deductible | E29: deductible | F29: deductible | G29: deductible | H29: deductible | I29: deductible
A30: Surgical Care Facility Fee | B30: Covered at 70%, subject to the deductible | C30: Covered at 100%, subject to the deductible | D30: Covered at 80%, subject to the deductible | E30: Covered at 60%, subject to the deductible | F30: Covered at 80%, subject to the deductible | G30: Covered at 60%, subject to the deductible | H30: Covered at 80%, subject to the deductible | I30: Covered at 60%, subject to the deductible
A31: Chemotherapy | B31: $50 copay per visit | C31: Covered at 100%, subject to the deductible | D31: Covered at 80%, subject to the deductible | E31: Covered at 60%, subject to the deductible | F31: Covered at 80%, subject to the deductible | G31: Covered at 60%, subject to the deductible | H31: Covered at 80%, subject to the deductible | I31: Covered at 60%, subject to the deductible
A32: Radiation Therapy | B32: $75 copay per visit | C32: Covered at 100%, subject to the deductible | D32: Covered at 80%, subject to the deductible | E32: Covered at 60%, subject to the deductible | F32: Covered at 80%, subject to the deductible | G32: Covered at 60%, subject to the deductible | H32: Covered at 80%, subject to the deductible | I32: Covered at 60%, subject to the deductible
A33: Inpatient mental health care | B33: Covered at 70% per admission for unlimited days, subject to the deductible | C33: Covered at 100% per admission for unlimited days, subject to the deductible | D33: Covered at 80% per admission for unlimited days, subject to the deductible | E33: Covered at 60% per admission for unlimited days, subject to the deductible | F33: Covered at 80% per admission for unlimited days, subject to the deductible | G33: Covered at 60% per admission for unlimited days, subject to the deductible | H33: Covered at 80% per admission for unlimited days, subject to the deductible | I33: Covered at 60% per admission for unlimited days, subject to the deductible
A34: Outpatient mental health care | B34: 3 visits covered in full. Next visits covered at | C34: Covered at 100%, subject to the deductible | D34: Covered at 80%, subject to the deductible | E34: Covered at 60%, subject to the deductible | F34: Covered at 80%, subject to the deductible | G34: Covered at 60%, subject to the deductible | H34: Covered at 80%, subject to the deductible | I34: Covered at 60%, subject to the deductible
B35: $50 copay per visit
